<?xml version="1.0"?>
<robot name="combined">
<!-- *********************************** CHASIS ********************************************** -->
  <!-- base_footprint -->
  <link name="base_footprint"/>
  <gazebo reference="base_footprint">
    <material value="Gazebo/Red"/>
  </gazebo>
  <!-- Chassis description -->
  <link name="base_link_p3dx">
    <!-- CHECK THESE VALUES. THEY MAY BE COMPLETELY WRONG. -->
    <inertial>
      <mass value="31.1"/>
      <origin xyz="0 0 0.148"/>
      <inertia ixx="0.3338" ixy="0.0" ixz="0.0" iyy="0.4783" iyz="0.0" izz="0.3338"/>
    </inertial>
    <!-- The base visual is fine. Just the inertial is questionable.-->
    <visual name="pioneer_geom">
      <origin rpy="0 0 0" xyz="0 0 0.148"/>
      <geometry name="pioneer_geom">
        <mesh filename="package://p3dx_urdf_model/meshes/p3dx_meshes/chassis.stl"/>
      </geometry>
      <material name="ChassisRed">
        <color rgba="0.851 0.0 0.0 1.0"/>
      </material>
    </visual>
    <collision>
      <origin rpy="0 0 0" xyz="-0.045 0 0.148"/>
      <geometry>
        <mesh filename="package://p3dx_urdf_model/meshes/p3dx_meshes/chassis.stl"/>
      </geometry>
    </collision>
  </link>
  <gazebo reference="base_link_p3dx">
    <material value="Gazebo/Red"/>
  </gazebo>
  <joint name="base_link_p3dx_joint" type="fixed">
    <origin rpy="0 0 0" xyz="0 0 0"/>
    <parent link="base_footprint"/>
    <child link="base_link_p3dx"/>
  </joint>
  <!-- Top part of the robot -->
  <link name="top_plate">
    <inertial>
      <mass value="0.01"/>
      <origin xyz="0 0 0"/>
      <inertia ixx="1" ixy="0" ixz="0" iyy="1" iyz="0" izz="1"/>
    </inertial>
    <visual name="pioneer_geom">
      <origin rpy="0 0 0" xyz="0 0 0"/>
      <geometry name="pioneer_geom">
        <mesh filename="package://p3dx_urdf_model/meshes/p3dx_meshes/top.stl"/>
      </geometry>
      <material name="TopBlack">
        <color rgba="0.038 0.038 0.038 1.0"/>
      </material>
    </visual>
  </link>
  <gazebo reference="top_plate">
    <material value="Gazebo/Black"/>
  </gazebo>
  <joint name="base_top_joint" type="fixed">
    <origin rpy="0.0 0.0 0.0" xyz="0.0 0.0 0.24"/>
    <parent link="base_link_p3dx"/>
    <child link="top_plate"/>
  </joint>
  <!-- ********************************************* CENTER WHEEL****************************************** -->
  <link name="swivel">
    <inertial>
      <mass value="0.1"/>
      <origin xyz="0 0 0"/>
      <inertia ixx="0.01" ixy="0" ixz="0" iyy="0.01" iyz="0" izz="0.01"/>
    </inertial>
    <visual name="pioneer_geom">
      <origin rpy="0 0 0" xyz="0 0 0"/>
      <geometry name="pioneer_geom">
        <mesh filename="package://p3dx_urdf_model/meshes/p3dx_meshes/swivel.stl"/>
      </geometry>
      <material name="swivel">
        <color rgba="0.5 0.5 0.5 1"/>
      </material>
    </visual>
    <collision>
      <origin rpy="0 0 0" xyz="0 0 0"/>
      <geometry>
        <box size="0 0 0"/>
      </geometry>
    </collision>
  </link>
  <gazebo reference="swivel">
    <material value="Gazebo/Grey"/>
  </gazebo>
  <!-- Center Wheel + Hubcap -->
  <link name="center_hubcap">
    <inertial>
      <mass value="0.01"/>
      <origin xyz="0 0 0"/>
      <inertia ixx="0.012411765597" ixy="-0.000711733678" ixz="0.00050272983" iyy="0.015218160428" iyz="-0.000004273467" izz="0.011763977943"/>
    </inertial>
    <visual name="pioneer_geom">
      <origin rpy="0 0 0" xyz="0 0 0"/>
      <geometry name="pioneer_geom">
        <mesh filename="package://p3dx_urdf_model/meshes/p3dx_meshes/center_hubcap.stl"/>
      </geometry>
      <material name="swivel">
        <color rgba="0.5 0.5 0.5 1"/>
      </material>
    </visual>
    <collision>
      <origin rpy="0 0 0" xyz="0 0 0"/>
      <geometry>
        <box size="0.05 0.05 0.05"/>
      </geometry>
    </collision>
  </link>
  <gazebo reference="center_hubcap">
    <material value="Gazebo/Grey"/>
  </gazebo>
  <link name="center_wheel">
    <inertial>
      <mass value="0.1"/>
      <origin xyz="0 0 0"/>
      <inertia ixx="0.012411765597" ixy="-0.000711733678" ixz="0.00050272983" iyy="0.015218160428" iyz="-0.000004273467" izz="0.011763977943"/>
    </inertial>
    <visual name="pioneer_geom">
      <origin rpy="0 0 0" xyz="0 0 0"/>
      <geometry name="pioneer_geom">
        <mesh filename="package://p3dx_urdf_model/meshes/p3dx_meshes/center_wheel.stl"/>
      </geometry>
      <material name="WheelBlack">
        <color rgba="0.117 0.117 0.117 1"/>
      </material>
    </visual>
    <collision>
      <origin rpy="-1.57079635 0 0" xyz="0 0 0"/>
      <geometry>
        <!--<mesh filename="package://p3dx_urdf_model/meshes/p3dx_meshes/center_wheel.stl"/>-->
        <cylinder length="0.01" radius="0.0375"/>
      </geometry>
    </collision>
  </link>
  <gazebo reference="left_hub">
    <material value="Gazebo/Yellow"/>
  </gazebo>
  <joint name="base_swivel_joint" type="fixed">
    <origin rpy="0 0 0" xyz="-0.185 0 0.055"/>
    <anchor xyz="0 1 0"/>
    <limit effort="100" k_velocity="0" velocity="100"/>
    <joint_properties damping="0.0" friction="0.0"/>
    <parent link="base_link_p3dx"/>
    <child link="swivel"/>
  </joint>
  <joint name="swivel_hubcap_joint" type="fixed">
    <origin rpy="0 0 0" xyz="-0.026 0 -0.016"/>
    <axis xyz="0 1 0"/>
    <anchor xyz="0 0 0"/>
    <limit effort="100" k_velocity="0" velocity="100"/>
    <joint_properties damping="0.0" friction="0.0"/>
    <parent link="swivel"/>
    <child link="center_wheel"/>
  </joint>
  <joint name="center_wheel_joint" type="fixed">
    <origin rpy="0 0 0" xyz="-0.0035 0 -0.001"/>
    <parent link="center_wheel"/>
    <child link="center_hubcap"/>
  </joint>
  <!-- LEFT WHEEL ***************************************************** -->
  <link name="left_hub">
    <visual>
      <origin rpy="0 0 0" xyz="0 0 0"/>
      <geometry>
        <mesh filename="package://p3dx_urdf_model/meshes/p3dx_meshes/left_hubcap.stl"/>
      </geometry>
      <material name="HubcapYellow">
        <color rgba="1.0 0.811 0.151 1.0"/>
      </material>
    </visual>
    <collision>
      <origin rpy="-1.57079635 0 0" xyz="0 0 0"/>
      <geometry>
        <!--<mesh filename="package://p3dx_urdf_model/meshes/p3dx_meshes/center_wheel.stl"/>-->
        <cylinder length="0.01" radius="0.09"/>
      </geometry>
    </collision>
  </link>
  <link name="base/joint0">
    <visual>
      <origin rpy="0 0 0" xyz="0 0 0"/>
      <geometry>
        <mesh filename="package://p3dx_urdf_model/meshes/p3dx_meshes/left_wheel.stl"/>
      </geometry>
      <material name="WheelBlack">
        <color rgba="0.117 0.117 0.117 1"/>
      </material>
    </visual>
  </link>
  <gazebo reference="left_wheel_joint">
    <material value="Gazebo/Black"/>
  </gazebo>
  <joint name="base/joint0" type="fixed">
    <origin rpy="0 0 0" xyz="0 0 0"/>
    <parent link="left_hub"/>
    <child link="base/joint0"/>
  </joint>
  <joint name="left_hub_joint" type="fixed">
    <origin rpy="0 0 0" xyz="0 0.15 0.08"/>
    <parent link="base_link_p3dx"/>
    <child link="left_hub"/>
    <axis xyz="0 1 0"/>
  </joint>
  <!-- RIGHT WHEEL ***************************************************************** -->
  <link name="right_hub">
    <visual>
      <origin rpy="0 0 0" xyz="0 0 0"/>
      <geometry>
        <mesh filename="package://p3dx_urdf_model/meshes/p3dx_meshes/right_hubcap.stl"/>
      </geometry>
      <material name="HubcapYellow">
        <color rgba="1.0 0.811 0.151 1.0"/>
      </material>
    </visual>
    <collision>
      <origin rpy="-1.57079635 0 0" xyz="0 0 0"/>
      <geometry>
        <!--<mesh filename="package://p3dx_urdf_model/meshes/p3dx_meshes/center_wheel.stl"/>-->
        <cylinder length="0.01" radius="0.09"/>
      </geometry>
    </collision>
  </link>
  <gazebo reference="right_hub">
    <material value="Gazebo/Yellow"/>
  </gazebo>
  <link name="base/joint1">
    <visual>
      <origin rpy="0 0 0" xyz="0 0 0"/>
      <geometry>
        <mesh filename="package://p3dx_urdf_model/meshes/p3dx_meshes/right_wheel.stl"/>
      </geometry>
      <material name="WheelBlack">
        <color rgba="0.117 0.117 0.117 1"/>
      </material>
    </visual>
  </link>
  <gazebo reference="right_wheel_joint">
    <material value="Gazebo/Black"/>
  </gazebo>
  <joint name="base/joint1" type="fixed">
    <origin rpy="0 0 0" xyz="0 0 0"/>
    <parent link="right_hub"/>
    <child link="base/joint1"/>
  </joint>
  <joint name="right_hub_joint" type="fixed">
    <origin rpy="0 0 0" xyz="0 -0.15 0.08"/>
    <parent link="base_link_p3dx"/>
    <child link="right_hub"/>
    <axis xyz="0 1 0"/>
  </joint>
  <sonar id="0" pitch="0" roll="0" x="0.1064" y="-0.1381" yaw="-1.5708" z="0.21"/>
  <sonar id="1" pitch="0" roll="0" x="0.1555" y="-0.1202" yaw="-0.8726999999999999" z="0.21"/>
  <sonar id="2" pitch="0" roll="0" x="+0.1906" y="-0.0785" yaw="-0.5236000000000001" z="0.21"/>
  <sonar id="3" pitch="0" roll="0" x="+0.2092" y="-0.0273" yaw="-0.17449999999999988" z="0.21"/>
  <sonar id="4" pitch="0" roll="0" x="+0.2092" y="+0.0273" yaw="0.17449999999999988" z="0.21"/>
  <sonar id="5" pitch="0" roll="0" x="+0.1906" y="+0.0831" yaw="0.5236000000000001" z="0.21"/>
  <sonar id="6" pitch="0" roll="0" x="+0.1554" y="+0.1251" yaw="0.8726999999999999" z="0.21"/>
  <sonar id="7" pitch="0" roll="0" x="+0.1064" y="+0.1382" yaw="1.5708" z="0.21"/>
  <!-- back side sonars -->
  <sonar id="8" pitch="0" roll="0" x="-0.1103" y="+0.1382" yaw="1.5708" z="0.21"/>
  <sonar id="9" pitch="0" roll="0" x="-0.1595" y="+0.1203" yaw="2.2689" z="0.21"/>
  <sonar id="10" pitch="0" roll="0" x="-0.1946" y="+0.0785" yaw="2.618" z="0.21"/>
  <sonar id="11" pitch="0" roll="0" x="-0.2132" y="+0.0273" yaw="2.9663" z="0.21"/>
  <sonar id="12" pitch="0" roll="0" x="-0.2132" y="-0.0273" yaw="2.9663" z="0.21"/>
  <sonar id="13" pitch="0" roll="0" x="-0.1946" y="-0.0785" yaw="-2.618" z="0.21"/>
  <sonar id="14" pitch="0" roll="0" x="-0.1595" y="-0.1202" yaw="-2.2693" z="0.21"/>
  <sonar id="15" pitch="0" roll="0" x="-0.1103" y="-0.1382" yaw="-1.5708" z="0.21"/>
  <bumper id="0" pitch="0" roll="0" x="+0.1767" y="-0.1700" yaw="-0.9498" z="0.0681"/>
  <bumper id="1" pitch="0" roll="0" x="+0.2377" y="-0.0909" yaw="-0.33899999999999997" z="0.0681"/>
  <bumper id="2" pitch="0" roll="0" x="+0.2549" y="0" yaw="0" z="0.0681"/>
  <bumper id="3" pitch="0" roll="0" x="+0.2377" y="+0.0909" yaw="0.3534999999999999" z="0.0681"/>
  <bumper id="4" pitch="0" roll="0" x="+0.1767" y="+0.1700" yaw="0.9701" z="0.0681"/>
  <bumper id="5" pitch="0" roll="0" x="-0.1476" y="+0.1712" yaw="2.0173" z="0.0681"/>
  <bumper id="6" pitch="0" roll="0" x="-0.2259" y="+0.0978" yaw="2.6281" z="0.0681"/>
  <bumper id="7" pitch="0" roll="0" x="-0.2553" y="0" yaw="-3.1416" z="0.0681"/>
  <bumper id="8" pitch="0" roll="0" x="-0.2259" y="-0.0978" yaw="-2.6079" z="0.0681"/>
  <bumper id="9" pitch="0" roll="0" x="-0.1476" y="-0.1712" yaw="-1.9969999999999999" z="0.0681"/>


  <!-- Run the macros -->
  <link name="base_link">
    <inertial>
      <origin rpy="0 0 0" xyz="0.00244324 0.00015573 0.08616742"/>
      <mass value="1.14608471"/>
      <inertia ixx="0.00335854" ixy="3.9E-07" ixz="0.00010989" iyy="0.003311" iyz="1.91E-06" izz="0.00077158"/>
    </inertial>
    <visual>
      <origin rpy="0 0 0" xyz="0 0 0"/>
      <geometry>
        <mesh filename="package://kortex_description/arms/gen3_lite/6dof/meshes/base_link.STL"/>
      </geometry>
      <material name="">
        <color rgba="0.803 0.824 0.820 1"/>
      </material>
    </visual>
    <collision>
      <origin rpy="0 0 0" xyz="0 0 0"/>
      <geometry>
        <mesh filename="package://kortex_description/arms/gen3_lite/6dof/meshes/base_link.STL"/>
      </geometry>
    </collision>
  </link>
  <gazebo reference="base_link">
    <material>Kortex/Gray</material>
  </gazebo>



<!-- JOINING LINK -->
<joint name="fixed_joint" type="fixed">
  <parent link="top_plate"/>
  <child link="base_link"/>
</joint>



  <link name="shoulder_link">
    <inertial>
      <origin rpy="0 0 0" xyz="2.477E-05 0.02213531 0.09937686"/>
      <mass value="0.95974404"/>
      <inertia ixx="0.00165947" ixy="2E-08" ixz="3.6E-07" iyy="0.00140355" iyz="0.00034927" izz="0.00089493"/>
    </inertial>
    <visual>
      <origin rpy="0 0 0" xyz="0 0 0"/>
      <geometry>
        <mesh filename="package://kortex_description/arms/gen3_lite/6dof/meshes/shoulder_link.STL"/>
      </geometry>
      <material name="">
        <color rgba="0.803 0.824 0.820 1"/>
      </material>
    </visual>
    <collision>
      <origin rpy="0 0 0" xyz="0 0 0"/>
      <geometry>
        <mesh filename="package://kortex_description/arms/gen3_lite/6dof/meshes/shoulder_link.STL"/>
      </geometry>
    </collision>
  </link>
  <gazebo reference="shoulder_link">
    <material>Kortex/Gray</material>
  </gazebo>
  <joint name="joint_1" type="revolute">
    <origin rpy="0 0 0" xyz="0 0 0.12825"/>
    <parent link="base_link"/>
    <child link="shoulder_link"/>
    <axis xyz="0 0 1"/>
    <limit effort="10" lower="-2.68" upper="2.68" velocity="1.6"/>
  </joint>
  <link name="arm_link">
    <inertial>
      <origin rpy="0 0 0" xyz="0.02998299 0.21154808 0.0453031"/>
      <mass value="1.17756164"/>
      <inertia ixx="0.01149277" ixy="1E-06" ixz="1.6E-07" iyy="0.00102851" iyz="0.00140765" izz="0.01133492"/>
    </inertial>
    <visual>
      <origin rpy="0 0 0" xyz="0 0 0"/>
      <geometry>
        <mesh filename="package://kortex_description/arms/gen3_lite/6dof/meshes/arm_link.STL"/>
      </geometry>
      <material name="">
        <color rgba="0.803 0.824 0.820 1"/>
      </material>
    </visual>
    <collision>
      <origin rpy="0 0 0" xyz="0 0 0"/>
      <geometry>
        <mesh filename="package://kortex_description/arms/gen3_lite/6dof/meshes/arm_link.STL"/>
      </geometry>
    </collision>
  </link>
  <gazebo reference="arm_link">
    <material>Kortex/Gray</material>
  </gazebo>
  <joint name="joint_2" type="revolute">
    <origin rpy="1.5708 0 0" xyz="0 -0.03 0.115"/>
    <parent link="shoulder_link"/>
    <child link="arm_link"/>
    <axis xyz="0 0 1"/>
    <limit effort="14" lower="-2.61" upper="2.61" velocity="1.6"/>
  </joint>
  <link name="forearm_link">
    <inertial>
      <origin rpy="0 0 0" xyz="0.0301559 0.09502206 0.0073555"/>
      <mass value="0.59767669"/>
      <inertia ixx="0.00163256" ixy="7.11E-06" ixz="1.54E-06" iyy="0.00029798" iyz="9.587E-05" izz="0.00169091"/>
    </inertial>
    <visual>
      <origin rpy="0 0 0" xyz="0 0 0"/>
      <geometry>
        <mesh filename="package://kortex_description/arms/gen3_lite/6dof/meshes/forearm_link.STL"/>
      </geometry>
      <material name="">
        <color rgba="0.803 0.824 0.820 1"/>
      </material>
    </visual>
    <collision>
      <origin rpy="0 0 0" xyz="0 0 0"/>
      <geometry>
        <mesh filename="package://kortex_description/arms/gen3_lite/6dof/meshes/forearm_link.STL"/>
      </geometry>
    </collision>
  </link>
  <gazebo reference="forearm_link">
    <material>Kortex/Gray</material>
  </gazebo>
  <joint name="joint_3" type="revolute">
    <origin rpy="-3.1416 0 0" xyz="0 0.28 0"/>
    <parent link="arm_link"/>
    <child link="forearm_link"/>
    <axis xyz="0 0 1"/>
    <limit effort="10" lower="-2.61" upper="2.61" velocity="1.6"/>
  </joint>
  <link name="lower_wrist_link">
    <inertial>
      <origin rpy="0 0 0" xyz="0.00575149 0.01000443 0.08719207"/>
      <mass value="0.52693412"/>
      <inertia ixx="0.00069098" ixy="2.4E-07" ixz="0.00016483" iyy="0.00078519" iyz="7.4E-07" izz="0.00034115"/>
    </inertial>
    <visual>
      <origin rpy="0 0 0" xyz="0 0 0"/>
      <geometry>
        <mesh filename="package://kortex_description/arms/gen3_lite/6dof/meshes/lower_wrist_link.STL"/>
      </geometry>
      <material name="">
        <color rgba="0.803 0.824 0.820 1"/>
      </material>
    </visual>
    <collision>
      <origin rpy="0 0 0" xyz="0 0 0"/>
      <geometry>
        <mesh filename="package://kortex_description/arms/gen3_lite/6dof/meshes/lower_wrist_link.STL"/>
      </geometry>
    </collision>
  </link>
  <gazebo reference="lower_wrist_link">
    <material>Kortex/Gray</material>
  </gazebo>
  <joint name="joint_4" type="revolute">
    <origin rpy="1.5708 0 0" xyz="0 -0.14 0.02"/>
    <parent link="forearm_link"/>
    <child link="lower_wrist_link"/>
    <axis xyz="0 0 1"/>
    <limit effort="7" lower="-2.6" upper="2.6" velocity="1.6"/>
  </joint>
  <link name="upper_wrist_link">
    <inertial>
      <origin rpy="0 0 0" xyz="0.08056517 0.00980409 0.01872799"/>
      <mass value="0.58097325"/>
      <inertia ixx="0.00021268" ixy="5.21E-06" ixz="2.91E-06" iyy="0.00106371" iyz="1.1E-07" izz="0.00108465"/>
    </inertial>
    <visual>
      <origin rpy="0 0 0" xyz="0 0 0"/>
      <geometry>
        <mesh filename="package://kortex_description/arms/gen3_lite/6dof/meshes/upper_wrist_link.STL"/>
      </geometry>
      <material name="">
        <color rgba="0.803 0.824 0.820 1"/>
      </material>
    </visual>
    <collision>
      <origin rpy="0 0 0" xyz="0 0 0"/>
      <geometry>
        <mesh filename="package://kortex_description/arms/gen3_lite/6dof/meshes/upper_wrist_link.STL"/>
      </geometry>
    </collision>
  </link>
  <gazebo reference="upper_wrist_link">
    <material>Kortex/Gray</material>
  </gazebo>
  <joint name="joint_5" type="revolute">
    <origin rpy="0 1.5708 0" xyz="0.0285 0 0.105"/>
    <parent link="lower_wrist_link"/>
    <child link="upper_wrist_link"/>
    <axis xyz="0 0 1"/>
    <limit effort="7" lower="-2.53" upper="2.53" velocity="1.6"/>
  </joint>
  <link name="end_effector_link"/>
  <joint name="joint_6" type="revolute">
    <origin rpy="0 -1.5708 0" xyz="-0.105 0 0.0285"/>
    <parent link="upper_wrist_link"/>
    <child link="end_effector_link"/>
    <axis xyz="0 0 1"/>
    <limit effort="7" lower="-2.6" upper="2.6" velocity="3.2"/>
  </joint>
  <link name="dummy_link"/>
  <joint name="end_effector" type="fixed">
    <origin rpy="0 0 0" xyz="0 0 0"/>
    <parent link="end_effector_link"/>
    <child link="dummy_link"/>
    <axis xyz="0 0 1"/>
    <limit effort="0" lower="0" upper="0" velocity="0"/>
  </joint>
  <!-- Tool frame used by the arm -->
  <link name="tool_frame"/>
  <joint name="tool_frame_joint" type="fixed">
    <origin rpy="0 0 1.57079632679" xyz="0 0 0.130"/>
    <parent link="dummy_link"/>
    <child link="tool_frame"/>
    <axis xyz="0 0 0"/>
  </joint>
  <!-- Gripper description -->
  <joint name="gripper_base_joint" type="fixed">
    <origin rpy="0 0 0" xyz="0 0 0"/>
    <parent link="dummy_link"/>
    <child link="gripper_base_link"/>
    <axis xyz="0 0 0"/>
  </joint>
  <link name="gripper_base_link">
    <inertial>
      <origin rpy="0 0 0" xyz="4.03E-06 1.08E-05 0.041397"/>
      <mass value="0.1395"/>
      <inertia ixx="0.00011614" ixy="1E-08" ixz="4E-08" iyy="0.00010327" iyz="0" izz="9.707E-05"/>
    </inertial>
    <visual>
      <origin rpy="0 0 0" xyz="0 0 0"/>
      <geometry>
        <mesh filename="package://kortex_description/grippers/gen3_lite_2f/meshes/gripper_base_link.STL"/>
      </geometry>
      <material name="">
        <color rgba="0.803 0.824 0.820 1"/>
      </material>
    </visual>
    <collision>
      <origin rpy="0 0 0" xyz="0 0 0"/>
      <geometry>
        <mesh filename="package://kortex_description/grippers/gen3_lite_2f/meshes/gripper_base_link.STL"/>
      </geometry>
    </collision>
  </link>
  <gazebo reference="gripper_base_link">
    <material>Kortex/Gray</material>
  </gazebo>
  <link name="right_finger_prox_link">
    <inertial>
      <origin rpy="0 0 0" xyz="0.020257 0.0063483 6.991E-05"/>
      <mass value="0.018385"/>
      <inertia ixx="2.29E-06" ixy="1.43E-06" ixz="0" iyy="4.56E-06" iyz="0" izz="4.77E-06"/>
    </inertial>
    <visual>
      <origin rpy="0 0 0" xyz="0 0 0"/>
      <geometry>
        <mesh filename="package://kortex_description/grippers/gen3_lite_2f/meshes/right_finger_prox_link.STL"/>
      </geometry>
      <material name="">
        <color rgba="0.803 0.824 0.820 1"/>
      </material>
    </visual>
    <collision>
      <origin rpy="0 0 0" xyz="0 0 0"/>
      <geometry>
        <mesh filename="package://kortex_description/grippers/gen3_lite_2f/meshes/right_finger_prox_link.STL"/>
      </geometry>
    </collision>
  </link>
  <gazebo reference="right_finger_prox_link">
    <material>Kortex/Gray</material>
  </gazebo>
  <joint name="right_finger_bottom_joint" type="revolute">
    <origin rpy="0 1.5708 0" xyz="0 -0.030501 0.070003"/>
    <parent link="gripper_base_link"/>
    <child link="right_finger_prox_link"/>
    <axis xyz="0 0 1"/>
    <limit effort="1000" lower="-0.09" upper="0.96" velocity="0.6"/>
  </joint>
  <link name="right_finger_dist_link">
    <inertial>
      <origin rpy="0 0 0" xyz="0.018488 0.0011091 0"/>
      <mass value="0.010748"/>
      <inertia ixx="6.3E-07" ixy="3.2E-07" ixz="0" iyy="1.83E-06" iyz="0" izz="1.61E-06"/>
    </inertial>
    <visual>
      <origin rpy="0 0 0" xyz="0 0 0"/>
      <geometry>
        <mesh filename="package://kortex_description/grippers/gen3_lite_2f/meshes/right_finger_dist_link.STL"/>
      </geometry>
      <material name="">
        <color rgba="0 0.055 0.525 1"/>
      </material>
    </visual>
    <collision>
      <origin rpy="0 0 0" xyz="0 0 0"/>
      <geometry>
        <mesh filename="package://kortex_description/grippers/gen3_lite_2f/meshes/right_finger_dist_link.STL"/>
      </geometry>
    </collision>
  </link>
  <gazebo reference="right_finger_dist_link">
    <material>Kortex/Blue</material>
  </gazebo>
  <joint name="right_finger_tip_joint" type="revolute">
    <origin rpy="0 0 0" xyz="-0.045636 0.020423 0"/>
    <parent link="right_finger_prox_link"/>
    <child link="right_finger_dist_link"/>
    <axis xyz="0 0 1"/>
    <limit effort="1000" lower="-0.50" upper="0.21" velocity="1000"/>
    <!--limit lower="-1.03" upper="0.21" effort="1000" velocity="1000" /-->
    <mimic joint="right_finger_bottom_joint" multiplier="-0.676" offset="0.149"/>
  </joint>
  <link name="left_finger_prox_link">
    <inertial>
      <origin rpy="0 0 0" xyz="0.020257 0.0063483 6.99E-05"/>
      <mass value="0.018385"/>
      <inertia ixx="2.29E-06" ixy="1.43E-06" ixz="0" iyy="4.56E-06" iyz="0" izz="4.77E-06"/>
    </inertial>
    <visual>
      <origin rpy="0 0 0" xyz="0 0 0"/>
      <geometry>
        <mesh filename="package://kortex_description/grippers/gen3_lite_2f/meshes/left_finger_prox_link.STL"/>
      </geometry>
      <material name="">
        <color rgba="0.803 0.824 0.820 1"/>
      </material>
    </visual>
    <collision>
      <origin rpy="0 0 0" xyz="0 0 0"/>
      <geometry>
        <mesh filename="package://kortex_description/grippers/gen3_lite_2f/meshes/left_finger_prox_link.STL"/>
      </geometry>
    </collision>
  </link>
  <gazebo reference="left_finger_prox_link">
    <material>Kortex/Gray</material>
  </gazebo>
  <joint name="left_finger_bottom_joint" type="revolute">
    <origin rpy="0 1.5708 0" xyz="0 0.0305 0.070003"/>
    <parent link="gripper_base_link"/>
    <child link="left_finger_prox_link"/>
    <axis xyz="0 0 1"/>
    <limit effort="1000" lower="-0.96" upper="0.09" velocity="1000"/>
    <mimic joint="right_finger_bottom_joint" multiplier="-1.0" offset="0.0"/>
  </joint>
  <link name="left_finger_dist_link">
    <inertial>
      <origin rpy="0 0 0" xyz="-0.018488 0.0011091 0"/>
      <mass value="0.010748"/>
      <inertia ixx="6.3E-07" ixy="3.2E-07" ixz="0" iyy="1.83E-06" iyz="0" izz="1.61E-06"/>
    </inertial>
    <visual>
      <origin rpy="0 0 0" xyz="0 0 0"/>
      <geometry>
        <mesh filename="package://kortex_description/grippers/gen3_lite_2f/meshes/left_finger_dist_link.STL"/>
      </geometry>
      <material name="">
        <color rgba="0 0.055 0.525 1"/>
      </material>
    </visual>
    <collision>
      <origin rpy="0 0 0" xyz="0 0 0"/>
      <geometry>
        <mesh filename="package://kortex_description/grippers/gen3_lite_2f/meshes/left_finger_dist_link.STL"/>
      </geometry>
    </collision>
  </link>
  <gazebo reference="left_finger_dist_link">
    <material>Kortex/Blue</material>
  </gazebo>
  <joint name="left_finger_tip_joint" type="revolute">
    <origin rpy="0 0 0" xyz="-0.045636 -0.020423 6.9901E-05"/>
    <parent link="left_finger_prox_link"/>
    <child link="left_finger_dist_link"/>
    <axis xyz="0 0 -1"/>
    <limit effort="1000" lower="-0.50" upper="0.21" velocity="1000"/>
    <!--limit lower="-1.03" upper="0.21" effort="1000" velocity="1000" /-->
    <mimic joint="right_finger_bottom_joint" multiplier="-0.676" offset="0.149"/>
  </joint>


</robot>
